Workbook

Sheet Порівняння
A1: Статус | B1: Що сталось | C1: Мій ID | D1: Мій товар | E1: Моя ціна, грн | F1: У мене в наявності | G1: Водоспад: ціна, грн | H1: Водоспад: наявність | I1: Клуб Рослин: ціна, грн | J1: Клуб Рослин: наявність | K1: Орієнтир | L1: Ціна орієнтира, грн | M1: Різниця, грн | N1: Різниця, % | O1: Зміна в орієнтира сьогодні, грн | P1: Змін в орієнтира за 30 днів | Q1: Розбіжність, днів | R1: Як зіставлено | S1: Мій товар
A2: Потребує уваги | B2: Ваша ціна нижча на 5150 грн (90.5%) | C2: 123100400 | D2: Точильний камінь 4000/1000 S&R (123100400) Німеччина | E2: 540 | F2: так | G2: 5690 | H2: так | K2: Водоспад | L2: 5690 | M2: =IF(L2="","",E2-L2) | N2: =IF(OR(L2="",L2=0),"",M2/L2) | P2: 0 | Q2: 1 | R2: код | S2: відкрити
A3: Потребує уваги | B3: Ваша ціна нижча на 4935 грн (86.7%) | C3: 123100402 | D3: Набір точильних каменів 120/240 та 4000/1000 гріт S&R (123100402) Німеччина | E3: 755 | F3: так | G3: 5690 | H3: так | K3: Водоспад | L3: 5690 | M3: =IF(L3="","",E3-L3) | N3: =IF(OR(L3="",L3=0),"",M3/L3) | P3: 0 | Q3: 1 | R3: код | S3: відкрити
A4: Потребує уваги | B4: Ваша ціна нижча на 750 грн (46.9%); Немає в наявності в жодного постачальника | C4: SD-95-PN | D4: Точилка діамантова для вигнутих країв АРС / ARS Pen (SD-95-PN) Японія | E4: 849 | F4: так | I4: 1599 | J4: ні | K4: Клуб Рослин | L4: 1599 | M4: =IF(L4="","",E4-L4) | N4: =IF(OR(L4="",L4=0),"",M4/L4) | P4: 0 | Q4: 1 | R4: код | S4: відкрити
A5: Потребує уваги | B5: Ваша ціна нижча на 1557 грн (26.8%) | C5: 0.600.8B2.100 | D5: Секатор Bosch EasyPrune акумуляторний (0.600.8B2.100) Німеччина | E5: 4245 | F5: ні | G5: 5802 | H5: ні | K5: Водоспад | L5: 5802 | M5: =IF(L5="","",E5-L5) | N5: =IF(OR(L5="",L5=0),"",M5/L5) | P5: 0 | Q5: 1 | R5: код | S5: відкрити
A6: Потребує уваги | B6: Ваша ціна нижча на 549 грн (19.6%) | C6: 7249 | D6: Добриво Преміум Фоліар Premium Foliar 19-19-19+ТЕ 15 кг AgroWork Туреччина | E6: 2250 | F6: ні | I6: 2799 | J6: ні | K6: Клуб Рослин | L6: 2799 | M6: =IF(L6="","",E6-L6) | N6: =IF(OR(L6="",L6=0),"",M6/L6) | P6: 0 | Q6: 1 | R6: код | S6: відкрити
A7: Потребує уваги | B7: Ваша ціна нижча на 33 грн (18.5%) | C7: 120500200101 | D7: Маркер перманентний Baumschulen чорний 2 мм (120500200101) Німеччина | E7: 145 | F7: ні | I7: 178 | J7: так | K7: Клуб Рослин | L7: 178 | M7: =IF(L7="","",E7-L7) | N7: =IF(OR(L7="",L7=0),"",M7/L7) | P7: 0 | Q7: 1 | R7: код | S7: відкрити
A8: Потребує уваги | B8: Ваша ціна нижча на 430 грн (16.6%) | C8: P57-25-F | D8: Кущоріз Bahco P57-25-F Бахо | E8: 2160 | F8: так | G8: 2590 | H8: так | K8: Водоспад | L8: 2590 | M8: =IF(L8="","",E8-L8) | N8: =IF(OR(L8="",L8=0),"",M8/L8) | P8: 0 | Q8: 1 | R8: код | S8: відкрити
A9: Потребує уваги | B9: Ваша ціна нижча на 450 грн (15.3%) | C9: PX-M3-R500P | D9: Секатор Bahco PX-M3 для обрізки саду | E9: 2500 | F9: ні | G9: 2050 | H9: ні | I9: 2950 | J9: так | K9: Клуб Рослин | L9: 2950 | M9: =IF(L9="","",E9-L9) | N9: =IF(OR(L9="",L9=0),"",M9/L9) | P9: 0 | Q9: 1 | R9: назва | S9: відкрити
A10: Потребує уваги | B10: Ваша ціна нижча на 100 грн (12.5%) | C10: 11827 | D10: Ніж Morakniv Companion MG Olive (11827) Mora Швеція | E10: 699 | F10: так | G10: 799 | H10: так | K10: Водоспад | L10: 799 | M10: =IF(L10="","",E10-L10) | N10: =IF(OR(L10="",L10=0),"",M10/L10) | P10: 0 | Q10: 1 | R10: код | S10: відкрити
A11: Потребує уваги | B11: Ваша ціна нижча на 22 грн (10.0%) | C11: Rain1 | D11: Опадомір (дощомір) пластиковий 0-50 mm L/m2 (Rain1) Corteva | E11: 198 | F11: ні | G11: 220 | H11: ні | K11: Водоспад | L11: 220 | M11: =IF(L11="","",E11-L11) | N11: =IF(OR(L11="",L11=0),"",M11/L11) | P11: 0 | Q11: 1 | R11: код | S11: відкрити
A12: Потребує уваги | B12: Ваша ціна нижча на 1474 грн (8.7%) | C12: BCL20IB | D12: Секатор акумуляторний Bahco BCL20IB Бахо | E12: 15525 | F12: ні | G12: 16999 | H12: ні | K12: Водоспад | L12: 16999 | M12: =IF(L12="","",E12-L12) | N12: =IF(OR(L12="",L12=0),"",M12/L12) | P12: 0 | Q12: 1 | R12: код | S12: відкрити
A13: Потребує уваги | B13: Ваша ціна нижча на 141 грн (8.3%) | C13: UV-32Е | D13: Пила АРС / ARS (UV-32E) серповидна з кобурою Японія | E13: 1549 | F13: ні | G13: 1690 | H13: так | K13: Водоспад | L13: 1690 | M13: =IF(L13="","",E13-L13) | N13: =IF(OR(L13="",L13=0),"",M13/L13) | P13: 0 | Q13: 1 | R13: код | S13: відкрити
A14: Потребує уваги | B14: Ваша ціна нижча на 40 грн (7.7%) | C14: 120500100606 | D14: Етикетки на дроті білі ПВХ 2.0 х 10 см 250 шт Німеччина | E14: 479 | F14: ні | I14: 519 | J14: так | K14: Клуб Рослин | L14: 519 | M14: =IF(L14="","",E14-L14) | N14: =IF(OR(L14="",L14=0),"",M14/L14) | P14: 0 | Q14: 1 | R14: код | S14: відкрити
A15: Потребує уваги | B15: Ваша ціна нижча на 55 грн (7.6%) | C15: 120500100703 | D15: Етикетки-кілочки для рослин PET-R білі 1.6 х 10 см 500 шт | E15: 670 | F15: ні | I15: 725 | J15: так | K15: Клуб Рослин | L15: 725 | M15: =IF(L15="","",E15-L15) | N15: =IF(OR(L15="",L15=0),"",M15/L15) | P15: 0 | Q15: 1 | R15: код | S15: відкрити
A16: Потребує уваги | B16: Ваша ціна нижча на 405 грн (7.5%) | C16: KST 231 | D16: Садові ножиці для живоплоту Окатсуне / Okatsune (KST 231) Японія | E16: 4985 | F16: так | G16: 5390 | H16: так | I16: 5390 | J16: так | K16: Водоспад | L16: 5390 | M16: =IF(L16="","",E16-L16) | N16: =IF(OR(L16="",L16=0),"",M16/L16) | P16: 0 | Q16: 1 | R16: код | S16: відкрити
A17: Потребує уваги | B17: Ваша ціна нижча на 13 грн (7.3%) | C17: 120500200110 | D17: Маркер перманентний Edding 400 чорний 1.0 мм Німеччина | E17: 165 | F17: ні | I17: 178 | J17: так | K17: Клуб Рослин | L17: 178 | M17: =IF(L17="","",E17-L17) | N17: =IF(OR(L17="",L17=0),"",M17/L17) | P17: 0 | Q17: 1 | R17: код | S17: відкрити
A18: Потребує уваги | B18: Ваша ціна нижча на 14 грн (7.0%) | C18: 120500200103 | D18: Маркер перманентний Pancolor Lumocolor 303F червоний 0.6 мм Staedtler Німеччина | E18: 186 | F18: ні | I18: 200 | J18: так | K18: Клуб Рослин | L18: 200 | M18: =IF(L18="","",E18-L18) | N18: =IF(OR(L18="",L18=0),"",M18/L18) | P18: 0 | Q18: 1 | R18: код | S18: відкрити
A19: Потребує уваги | B19: Ваша ціна нижча на 14 грн (7.0%) | C19: 120500200104 | D19: Маркер перманентний Pancolor Lumocolor 303M чорний 1.0 мм (120500200104) Staedtler Німеччина | E19: 186 | F19: ні | I19: 200 | J19: так | K19: Клуб Рослин | L19: 200 | M19: =IF(L19="","",E19-L19) | N19: =IF(OR(L19="",L19=0),"",M19/L19) | P19: 0 | Q19: 1 | R19: код | S19: відкрити
A20: Потребує уваги | B20: Ваша ціна нижча на 36 грн (6.7%) | C20: P127-19 | D20: Ножиці для збору врожаю P127-19 Bahco | E20: 504 | F20: так | I20: 540 | J20: так | K20: Клуб Рослин | L20: 540 | M20: =IF(L20="","",E20-L20) | N20: =IF(OR(L20="",L20=0),"",M20/L20) | P20: 0 | Q20: 1 | R20: код | S20: відкрити
A21: Потребує уваги | B21: Ваша ціна нижча на 300 грн (6.7%) | C21: 5386 | D21: Садові ножиці для кущів Окатсуне / Okatsune (KST 216) | E21: 4190 | F21: ні | G21: 4490 | H21: так | I21: 4490 | J21: так | K21: Водоспад | L21: 4490 | M21: =IF(L21="","",E21-L21) | N21: =IF(OR(L21="",L21=0),"",M21/L21) | P21: 0 | Q21: 1 | R21: код
A22: Потребує уваги | B22: Ваша ціна нижча на 300 грн (6.7%) | C22: KST 216 | D22: Садові ножиці для кущів Окатсуне / Okatsune (KST216) Японія | E22: 4190 | F22: ні | G22: 4490 | H22: так | I22: 4490 | J22: так | K22: Водоспад | L22: 4490 | M22: =IF(L22="","",E22-L22) | N22: =IF(OR(L22="",L22=0),"",M22/L22) | P22: 0 | Q22: 1 | R22: код | S22: відкрити
A23: Потребує уваги | B23: Ваша ціна нижча на 139 грн (6.5%) | C23: 2C 380/20 | D23: Секатор Due Cigni 200 мм (2C 380/20) Італія | E23: 1990 | F23: ні | G23: 2129 | H23: так | K23: Водоспад | L23: 2129 | M23: =IF(L23="","",E23-L23) | N23: =IF(OR(L23="",L23=0),"",M23/L23) | P23: 0 | Q23: 1 | R23: код | S23: відкрити
A24: Потребує уваги | B24: Ваша ціна нижча на 53 грн (4.9%) | C24: R260A | D24: Запасне опорне лезо для сучкоріза Bahco P-160 R260A | E24: 1037 | F24: так | G24: 1090 | H24: так | I24: 1090 | J24: так | K24: Водоспад | L24: 1090 | M24: =IF(L24="","",E24-L24) | N24: =IF(OR(L24="",L24=0),"",M24/L24) | P24: 0 | Q24: 1 | R24: код | S24: відкрити
A25: Потребує уваги | B25: Ваша ціна нижча на 5 грн (4.8%) | C25: 23FCSPE12 | D25: Підв`язка для рослин 12 см Х 1000 шт гнучкий сталевий дріт у паперовій оболонці (23FCSPE12) Італія | E25: 100 | F25: так | G25: 105 | H25: так | K25: Водоспад | L25: 105 | M25: =IF(L25="","",E25-L25) | N25: =IF(OR(L25="",L25=0),"",M25/L25) | P25: 0 | Q25: 1 | R25: код | S25: відкрити
A26: Потребує уваги | B26: Ваша ціна нижча на 60 грн (4.8%) | C26: KST404 | D26: Серп садовий Окатсуне / Okatsune (KST 404) Японія | E26: 1190 | F26: так | G26: 1250 | H26: так | I26: 1190 | J26: ні | K26: Водоспад | L26: 1250 | M26: =IF(L26="","",E26-L26) | N26: =IF(OR(L26="",L26=0),"",M26/L26) | P26: 0 | Q26: 1 | R26: код | S26: відкрити
A27: Потребує уваги | B27: Ваша ціна нижча на 15 грн (4.3%) | C27: 23FIPEGRVS3 | D27: Агротрубка (кембрик) для підв`язки рослин 3 мм 1 кг 230 м Super extra cordioli (23FIPEGRVS3) Італія | E27: 330 | F27: так | G27: 345 | H27: так | K27: Водоспад | L27: 345 | M27: =IF(L27="","",E27-L27) | N27: =IF(OR(L27="",L27=0),"",M27/L27) | P27: 0 | Q27: 1 | R27: код | S27: відкрити
A28: Потребує уваги | B28: Ваша ціна нижча на 200 грн (4.3%) | C28: Lopata_M | D28: Лопата саперна Нівакі / Niwaki 820x160x28 мм 0.98 кг (Lopata_M) Японія | E28: 4399 | F28: ні | G28: 4599 | H28: ні | K28: Водоспад | L28: 4599 | M28: =IF(L28="","",E28-L28) | N28: =IF(OR(L28="",L28=0),"",M28/L28) | P28: 0 | Q28: 1 | R28: код | S28: відкрити
A29: Потребує уваги | B29: Ваша ціна нижча на 40 грн (4.0%) | C29: KST108 | D29: Чохол шкіряний Окатсуне / Okatsune (KST108) Японія | E29: 950 | F29: так | G29: 990 | H29: так | I29: 890 | J29: ні | K29: Водоспад | L29: 990 | M29: =IF(L29="","",E29-L29) | N29: =IF(OR(L29="",L29=0),"",M29/L29) | P29: 0 | Q29: 1 | R29: код | S29: відкрити
A30: Потребує уваги | B30: Ваша ціна нижча на 51 грн (3.9%) | C30: 6b06622a-abbb-11ee-bf43-c87f546feb15 | D30: Лопата штикова Bellota 3103 MFVA.B Іспанія | E30: 1259 | F30: ні | I30: 1310 | J30: так | K30: Клуб Рослин | L30: 1310 | M30: =IF(L30="","",E30-L30) | N30: =IF(OR(L30="",L30=0),"",M30/L30) | P30: 0 | Q30: 1 | R30: схожа назва
A31: Потребує уваги | B31: Ваша ціна нижча на 180 грн (3.8%) | C31: 7d31f229-bf5c-11ee-bf58-c87f546feb15 | D31: Коса 660 мм Bellota 2509-26.B Іспанія | E31: 4499 | F31: ні | I31: 4679 | J31: так | K31: Клуб Рослин | L31: 4679 | M31: =IF(L31="","",E31-L31) | N31: =IF(OR(L31="",L31=0),"",M31/L31) | P31: 0 | Q31: 1 | R31: код
A32: Потребує уваги | B32: Ваша ціна нижча на 42 грн (3.5%) | C32: R185V | D32: Запасне лезо для гілкоріза Bahco P280 (R185V) | E32: 1148 | F32: так | G32: 1190 | H32: так | K32: Водоспад | L32: 1190 | M32: =IF(L32="","",E32-L32) | N32: =IF(OR(L32="",L32=0),"",M32/L32) | P32: 0 | Q32: 1 | R32: код | S32: відкрити
A33: Потребує уваги | B33: Ваша ціна нижча на 90 грн (3.0%) | C33: 446-24 | D33: Садова пила складна Silky Ultra Accel Curve 240-7.5 (446-24) Японія | E33: 2900 | F33: ні | G33: 2990 | H33: так | K33: Водоспад | L33: 2990 | M33: =IF(L33="","",E33-L33) | N33: =IF(OR(L33="",L33=0),"",M33/L33) | P33: 0 | Q33: 1 | R33: код | S33: відкрити
A34: Потребує уваги | B34: Ваша ціна нижча на 10 грн (2.9%) | C34: 23FIPEGRVS2 | D34: Агротрубка (кембрик) для підв`язки рослин 2 мм 1кг 320 м Super extra cordioli (23FIPEGRVS2) Італія | E34: 340 | F34: так | G34: 350 | H34: так | K34: Водоспад | L34: 350 | M34: =IF(L34="","",E34-L34) | N34: =IF(OR(L34="",L34=0),"",M34/L34) | P34: 0 | Q34: 1 | R34: код | S34: відкрити
A35: Потребує уваги | B35: Ваша ціна нижча на 10 грн (2.8%) | C35: 23FIPEGRVS6 | D35: Агротрубка (кембрик) для підв`язки рослин 6 мм 1 кг 98 м Super extra cordioli (23FIPEGRVS6) Італія | E35: 350 | F35: так | G35: 360 | H35: так | K35: Водоспад | L35: 360 | M35: =IF(L35="","",E35-L35) | N35: =IF(OR(L35="",L35=0),"",M35/L35) | P35: 0 | Q35: 1 | R35: код | S35: відкрити
A36: Потребує уваги | B36: Ваша ціна нижча на 40 грн (2.8%) | C36: LAP-KNIFE | D36: Набір Bahco laplander 396 пилка + Knife 2446 ніж (LAP-KNIFE) | E36: 1390 | F36: так | G36: 1430 | H36: так | K36: Водоспад | L36: 1430 | M36: =IF(L36="","",E36-L36) | N36: =IF(OR(L36="",L36=0),"",M36/L36) | P36: 0 | Q36: 1 | R36: назва | S36: відкрити
A37: Потребує уваги | B37: Ваша ціна нижча на 10 грн (2.2%) | C37: 121000332326 | D37: Масло камелии антикоррозионное Kurobara Tsubak 100 млi Hanakumagawa Япония | E37: 445 | F37: ні | I37: 455 | J37: так | K37: Клуб Рослин | L37: 455 | M37: =IF(L37="","",E37-L37) | N37: =IF(OR(L37="",L37=0),"",M37/L37) | P37: 0 | Q37: 1 | R37: код
A38: Потребує уваги | B38: Ваша ціна нижча на 42 грн (1.9%) | C38: P34-27A-F | D38: Висоторіз Bahco P34-27A-F | E38: 2148 | F38: так | G38: 2190 | H38: так | I38: 2190 | J38: так | K38: Водоспад | L38: 2190 | M38: =IF(L38="","",E38-L38) | N38: =IF(OR(L38="",L38=0),"",M38/L38) | P38: 0 | Q38: 1 | R38: код | S38: відкрити
A39: Потребує уваги | B39: Ваша ціна нижча на 5 грн (1.5%) | C39: 5170007N | D39: Віск для щеплення червоний гранульований з фунгіцидами Plastigreffe 6535 - 500 г (5170007N) AgriChem Італія | E39: 320 | F39: так | G39: 325 | H39: так | K39: Водоспад | L39: 325 | M39: =IF(L39="","",E39-L39) | N39: =IF(OR(L39="",L39=0),"",M39/L39) | P39: 0 | Q39: 1 | R39: код | S39: відкрити
A40: Потребує уваги | B40: Ваша ціна нижча на 60 грн (1.5%) | C40: P160-SL-75 | D40: Гілкоріз Bahco P160-SL-75 | E40: 3990 | F40: так | G40: 4050 | H40: так | I40: 4050 | J40: так | K40: Водоспад | L40: 4050 | M40: =IF(L40="","",E40-L40) | N40: =IF(OR(L40="",L40=0),"",M40/L40) | P40: 0 | Q40: 1 | R40: код | S40: відкрити
...

Sheet Журнал змін
A1: Дата | B1: Хто змінив | C1: Мій ID | D1: ID у постачальника | E1: Товар | F1: Було, грн | G1: Стало, грн | H1: Зміна, грн | I1: Зміна, %

Sheet Ціни постачальників по днях
A1: Постачальник | B1: Мій ID | C1: ID у постачальника | D1: Товар | E1: 08.10
A2: Водоспад | B2: 123100400 | C2: 42494 | D2: Точильний камінь 4000/1000 S&R (123100400) Німеччина | E2: 5690
A3: Водоспад | B3: 123100402 | C3: 42494 | D3: Набір точильних каменів 120/240 та 4000/1000 гріт S&R (123100402) Німеччина | E3: 5690
A4: Клуб Рослин | B4: SD-95-PN | C4: 15592 | D4: Точилка діамантова для вигнутих країв АРС / ARS Pen (SD-95-PN) Японія | E4: 1599
A5: Водоспад | B5: 0.600.8B2.100 | C5: 41370 | D5: Секатор Bosch EasyPrune акумуляторний (0.600.8B2.100) Німеччина | E5: 5802
A6: Клуб Рослин | B6: 7249 | C6: 15530 | D6: Добриво Преміум Фоліар Premium Foliar 19-19-19+ТЕ 15 кг AgroWork Туреччина | E6: 2799
A7: Клуб Рослин | B7: 120500200101 | C7: 10596 | D7: Маркер перманентний Baumschulen чорний 2 мм (120500200101) Німеччина | E7: 178
A8: Водоспад | B8: P57-25-F | C8: 42609 | D8: Кущоріз Bahco P57-25-F Бахо | E8: 2590
A9: Водоспад | B9: PX-M3-R500P | C9: 37459 | D9: Секатор Bahco PX-M3 для обрізки саду | E9: 2050
A10: Клуб Рослин | B10: PX-M3-R500P | C10: 11858 | D10: Секатор Bahco PX-M3 для обрізки саду | E10: 2950
A11: Водоспад | B11: 11827 | C11: 41088 | D11: Ніж Morakniv Companion MG Olive (11827) Mora Швеція | E11: 799
A12: Водоспад | B12: Rain1 | C12: 40534 | D12: Опадомір (дощомір) пластиковий 0-50 mm L/m2 (Rain1) Corteva | E12: 220
A13: Водоспад | B13: BCL20IB | C13: 39101 | D13: Секатор акумуляторний Bahco BCL20IB Бахо | E13: 16999
... A675: Водоспад | B675: 3.90.20 | C675: 32375 | D675: ​​​​​​​Ніж для щеплення Victorinox 3.90.20 Швейцарія | E675: 1449

Sheet Ваші ціни по днях
A1: Постачальник | B1: Мій ID | C1: ID у постачальника | D1: Товар | E1: 08.10
A2: Водоспад | B2: 123100400 | C2: 42494 | D2: Точильний камінь 4000/1000 S&R (123100400) Німеччина | E2: 540
A3: Водоспад | B3: 123100402 | C3: 42494 | D3: Набір точильних каменів 120/240 та 4000/1000 гріт S&R (123100402) Німеччина | E3: 755
A4: Клуб Рослин | B4: SD-95-PN | C4: 15592 | D4: Точилка діамантова для вигнутих країв АРС / ARS Pen (SD-95-PN) Японія | E4: 849
A5: Водоспад | B5: 0.600.8B2.100 | C5: 41370 | D5: Секатор Bosch EasyPrune акумуляторний (0.600.8B2.100) Німеччина | E5: 4245
A6: Клуб Рослин | B6: 7249 | C6: 15530 | D6: Добриво Преміум Фоліар Premium Foliar 19-19-19+ТЕ 15 кг AgroWork Туреччина | E6: 2250
A7: Клуб Рослин | B7: 120500200101 | C7: 10596 | D7: Маркер перманентний Baumschulen чорний 2 мм (120500200101) Німеччина | E7: 145
A8: Водоспад | B8: P57-25-F | C8: 42609 | D8: Кущоріз Bahco P57-25-F Бахо | E8: 2160
A9: Водоспад | B9: PX-M3-R500P | C9: 37459 | D9: Секатор Bahco PX-M3 для обрізки саду | E9: 2500
A10: Клуб Рослин | B10: PX-M3-R500P | C10: 11858 | D10: Секатор Bahco PX-M3 для обрізки саду | E10: 2500
A11: Водоспад | B11: 11827 | C11: 41088 | D11: Ніж Morakniv Companion MG Olive (11827) Mora Швеція | E11: 699
A12: Водоспад | B12: Rain1 | C12: 40534 | D12: Опадомір (дощомір) пластиковий 0-50 mm L/m2 (Rain1) Corteva | E12: 198
A13: Водоспад | B13: BCL20IB | C13: 39101 | D13: Секатор акумуляторний Bahco BCL20IB Бахо | E13: 15525
... A675: Водоспад | B675: 3.90.20 | C675: 32375 | D675: ​​​​​​​Ніж для щеплення Victorinox 3.90.20 Швейцарія | E675: 1449

Sheet Пари на перевірку
A1: Скрипт не наважився зіставити ці товари сам. Щоб підтвердити пару, відкрийте mapping/suggestions.csv на GitHub і впишіть «так» у колонку «рішення», щоб відхилити, «ні».
A2: Схожість | B2: Постачальник | C2: Мій ID | D2: ID у постачальника | E2: Мій товар | F2: Товар постачальника | G2: Моя ціна, грн | H2: Ціна постачальника, грн | I2: Причина
A3: 97.2 | B3: Водоспад | C3: 8.107 | D3: 32356 | E3: Садовий секатор із наковаленкою LOWE Original 8.107 | F3: Садовий секатор із наковаленкою LOWE Original 8.107 (8.107) | G3: 2990 | H3: 2990 | I3: назви схожі, перевірте
A4: 97.1 | B4: Водоспад | C4: BCL25IB | D4: 39101 | E4: Секатор акумуляторний Bahco BCL25IB | F4: Акумуляторний секатор Bahco (BCL20IB) | G4: 33750 | H4: 16999 | I4: назви схожі, перевірте
A5: 95.7 | B5: Водоспад | C5: BCL240 | D5: 39101 | E5: Секатор акумуляторний Bahco BCL240 | F5: Акумуляторний секатор Bahco (BCL20IB) | G5: 20025 | H5: 16999 | I5: назви схожі, але різні коди виробника
A6: 95.6 | B6: Водоспад | C6: PROF-H | D6: 42566 | E6: Шкіряний чохол Bahco PROF-H Бахо | F6: Чохол шкіряний BAHCO (PROF-H) | G6: 1350 | H6: 1390 | I6: назви схожі, різняться словами: бахо
A7: 95 | B7: Клуб Рослин | C7: 5770/R | D7: 10823 | E7: Ніж для щеплення універсальний високовуглецева сталь хобі Антоніні / Antonini (5770/R) Італія | F7: Ніж Antonini 5770/R для щеплення універсальний високовуглецева сталь хобі | G7: 450 | H7: 450 | I7: назви схожі, різняться словами: антоніні
A8: 94.7 | B8: Клуб Рослин | C8: 702 | D8: 15822 | E8: Секатор садовий обвідний Йошіока Хамоно / Yoshioka Hamono (702) | F8: Секатор Yoshioka Hamono 702 японський садовий обвідний (Йошіока Хамоно 702) | G8: 1990 | H8: 1990 | I8: назви схожі, різняться словами: японський
A9: 94.7 | B9: Клуб Рослин | C9: 701-1 | D9: 15821 | E9: Секатор садовий обвідний Йошіока Хамоно / Yoshioka Hamono (701) | F9: Секатор Yoshioka Hamono 701 японський садовий обвідний (Йошіока Хамоно 701) | G9: 1890 | H9: 1890 | I9: назви схожі, різняться словами: японський
A10: 94.7 | B10: Клуб Рослин | C10: 5016/L | D10: 10810 | E10: Ніж для щеплення універсальний високовуглецева сталь Антоніні / Antonini (5016/L) Італія | F10: Ніж Antonini 5016/L для щеплення універсальний високовуглецева сталь | G10: 1260 | H10: 1130 | I10: назви схожі, різняться словами: антоніні
A11: 94.7 | B11: Клуб Рослин | C11: 5016/N | D11: 10812 | E11: Ніж для щеплення універсальний високовуглецева сталь Антоніні / Antonini (5016/N) Італія | F11: Ніж Antonini 5016/N для щеплення універсальний високовуглецева сталь | G11: 1130 | H11: 1130 | I11: назви схожі, різняться словами: антоніні
A12: 94.7 | B12: Клуб Рослин | C12: 5016/R | D12: 10813 | E12: Ніж для щеплення універсальний високовуглецева сталь Антоніні / Antonini (5016/R) Італія | F12: Ніж Antonini 5016/R для щеплення універсальний високовуглецева сталь | G12: 1130 | H12: 1130 | I12: назви схожі, різняться словами: антоніні
A13: 94.6 | B13: Водоспад | C13: 9.107 | D13: 32327 | E13: LOWE Original 9.107 обхідний секатор Німеччина | F13: Обхідний секатор LOWE 9.107 (Німеччина) | G13: 3190 | H13: 3190 | I13: назви схожі, різняться словами: original
A14: 94.6 | B14: Водоспад | C14: 9.104 | D14: 32326 | E14: LOWE Original 9.104 Обхідний секатор Німеччина | F14: Обхідний секатор LOWE 9.104 (Німеччина) | G14: 3190 | H14: 3190 | I14: назви схожі, різняться словами: original
... A45: 90.5 | B45: Клуб Рослин | C45: 640 | D45: 11216 | E45: Пила в кобурі 440 мм Фелко / Felco 640 Швейцарія | F45: Пила в кобурі Felco 640 (Фелко 640) | G45: 3490 | H45: 3490 | I45: назви схожі, перевірте
A46: 90.5 | B46: Клуб Рослин | C46: ddd10be1-abba-11ee-bf43-c87f546feb15 | D46: 9622 | E46: Окуляри захисні | F46: Захисні окуляри LESO-TR | H46: 70 | I46: назви схожі, різняться словами: lesotr
A47: 90.4 | B47: Водоспад | C47: 605/11 | D47: 32936 | E47: Щеплювальний ніж універсальний Тіна / Tina (605/11) Німеччина | F47: Ніж універсальний TINA 605/11 (Німеччина) | G47: 4999 | H47: 4999 | I47: назви схожі, різняться словами: тіна, щеплювальний
A48: 90.4 | B48: Клуб Рослин | C48: 3604-21.B | D48: 11876 | E48: Секатор 210 мм універсальний Bellota (3604-21.B) Іспанія | F48: Секатор Bellota 3604-21 універсальний | G48: 1989 | H48: 1989 | I48: назви схожі, але різні коди виробника
A49: 90.3 | B49: Клуб Рослин | C49: SR-BAG.L | D49: 16238 | E49: Сумка Смарт Рейн / Smart Rain 400 л (SR-BAG.L) | F49: Сумка Smart Rain 280 л SR-BAG (Смарт Рейн SR-BAG) | G49: 995 | H49: 695 | I49: назви схожі, але різні об'єми або розміри
A50: 90.3 | B50: Клуб Рослин | C50: 646283f3-abbb-11ee-bf43-c87f546feb15 | D50: 11884 | E50: Секатор Due Buoi 175 см (1145/17.5) типу ножиці довгі леза Дю Буі | F50: Секатор Due Buoi 1145/17,5 типу ножиці довгі леза (Дуе Буаї) | G50: 419 | H50: 496 | I50: код збігся, але різні коди виробника
A51: 90.2 | B51: Клуб Рослин | C51: P6202 | D51: 16018 | E51: Серп-коса для трави 37 см Фукс / Fux (P6202) Австрія | F51: Серп-Коса 35 см FUX 2 для трави (Фукс P6202) | G51: 2650 | H51: 2650 | I51: назви схожі, але різні об'єми або розміри
A52: 90 | B52: Водоспад | C52: 606 | D52: 32935 | E52: Щеплювальний ніж універсальний Тіна / Tina (606) Німеччина | F52: Ніж універсальний TINA 606 (Німеччина) | G52: 4799 | H52: 4799 | I52: назви схожі, різняться словами: тіна, щеплювальний
A53: 90 | B53: Водоспад | C53: 605 | D53: 32806 | E53: Щеплювальний ніж універсальний Тіна / Tina (605) Німеччина | F53: Ніж універсальний TINA 605 (Німеччина) | G53: 4799 | H53: 4799 | I53: назви схожі, різняться словами: тіна, щеплювальний
A54: 90 | B54: Клуб Рослин | C54: 3512-21.B | D54: 11872 | E54: Секатор 210 мм професійний Bellota (3512-21.B) Іспанія | F54: Секатор Bellota 3512-21 професійний | G54: 2798 | H54: 2798 | I54: назви схожі, але різні коди виробника
A55: 90 | B55: Клуб Рослин | C55: 3510-21.B | D55: 11871 | E55: Секатор 210 мм професійний Bellota (3510-21.B) Іспанія | F55: Секатор Bellota 3510-21 професійний | G55: 2649 | H55: 2649 | I55: назви схожі, але різні коди виробника
A56: 90 | B56: Клуб Рослин | C56: CAM-24LN | D56: 11177 | E56: Пила АРС / ARS (CAM-24LN) з кобурою Японія | F56: Пила з кобурою ARS CAM-24LN (АРС CAM-24LN) | G56: 1459 | H56: 1459 | I56: назви схожі, але різні коди виробника
A57: 89.9 | B57: Клуб Рослин | C57: VS-9XZ | D57: 11843 | E57: Секатор АРС / ARS (VS-9XZ) професійний обвідний Японія | F57: Секатор ARS VS-9Z професійний обвідний (АРС VS-9Z) | G57: 2519 | H57: 1490 | I57: назви схожі, але різні коди виробника
A58: 89.8 | B58: Клуб Рослин | C58: 7104 | D58: 9312 | E58: Добриво Монокалій фосфат 0-52-34 Nova Peak 25 кг ICL Ізраїль | F58: Добриво водорозчинне Монокалій фосфат ICL Novapeak 0-52-34 (Ізраїль), 25 кг | G58: 3798 | H58: 3950 | I58: назви схожі, різняться словами: водорозчинне
... A79: 88.5 | B79: Клуб Рослин | C79: 3461-C.B. | D79: 11019 | E79: Ножиці для обрізки кущів Bellota (3461-C.B.) Іспанія | F79: Ножиці для кущів Bellota 3461-C | G79: 1845 | H79: 2287 | I79: назви схожі, різняться словами: обрізки
A80: 88.2 | B80: Водоспад | C80: ddd10b7f-abba-11ee-bf43-c87f546feb15 | D80: 38700 | E80: Садові ножиці | F80: Садові ножиці ARS (310) | H80: 445 | I80: назви схожі, різняться словами: ars
A81: 88.1 | B81: Клуб Рослин | C81: 3510-21D.B | D81: 12061 | E81: Секатор 210 мм професійний для великих рук Bellota (3510-21D.B) Іспанія | F81: Секатор професійний Bellota 3512-22.B для великих рук | G81: 2369 | H81: 1909 | I81: назви схожі, але різні коди виробника
A82: 88.1 | B82: Клуб Рослин | C82: 3556.B | D82: 11047 | E82: Ножиці довгомірні для підрізування трави Bellota (3556.B) Іспанія | F82: Ножиці довгомірні Bellota 3556.B для підрізки трави | G82: 2314 | H82: 2314 | I82: назви схожі, різняться словами: підрізки, підрізування
A83: 88.1 | B83: Клуб Рослин | C83: HT-R11 | D83: 10978 | E83: Ніж для степлера HT-R1 MAX Tapener (комплект 2шт) | F83: Ніж для степлера HR-F Max (комплект 5шт) | G83: 250 | H83: 230 | I83: назви схожі, але різні об'єми або розміри
A84: 88 | B84: Водоспад | C84: 3083.B | D84: 43391 | E84: Сапка рамкова без держака 150 мм Bellota (3083.B) Іспанія | F84: Сапка рамкова Bellota 3083.B (плоскоріз) 150 мм без держака | G84: 485 | H84: 469 | I84: назви схожі, різняться словами: плоскоріз
A85: 88 | B85: Клуб Рослин | C85: 611 | D85: 11213 | E85: Пила в кобурі 500 мм Felco / Фелко 611 Швейцарія | F85: Пила в кобурі Felco 611 (Фелко 611) | G85: 2990 | H85: 2990 | I85: назви схожі, перевірте
A86: 87.8 | B86: Водоспад | C86: N9.107 | D86: 43329 | E86: Секатор обвідний Lowe Natural Series (N9.107) дерев’яні ручки Німеччина | F86: Секатор обвідний LOWE N9.107 Natural Series, зріз 22 мм, дерев’яні ручки з гікорі | G86: 5499 | H86: 5499 | I86: назви схожі, різняться словами: гікорі, зріз
A87: 87.8 | B87: Водоспад | C87: N9.104 | D87: 43323 | E87: Секатор обвідний Lowe Natural Series (N9.104) дерев’яні ручки Німеччина | F87: Секатор обвідний LOWE N9.104 Natural Series, зріз 22 мм, дерев’яні ручки з гікорі | G87: 5499 | H87: 5499 | I87: назви схожі, різняться словами: гікорі, зріз
A88: 87.8 | B88: Водоспад | C88: 3580-CH.B | D88: 37700 | E88: Запасне контрлезо для гілкоріза 3580 (3580-CH.B) Bellota Іспанія | F88: Запасне контрлезо 3580 Bellota (3580-CH) | G88: 1259 | H88: 1210 | I88: назви схожі, але різні коди виробника
A89: 87.7 | B89: Клуб Рослин | C89: 3344 | D89: 12851 | E89: Фунгіцид Парацельс 100 мл Сімейний Сад Україна | F89: Фунгіцид Парацельс К.С. (флутриафол) 100 мл Сімейний Сад | G89: 198 | H89: 178 | I89: назви схожі, різняться словами: флутриафол
A90: 87.6 | B90: Клуб Рослин | C90: 3505-23.B | D90: 12061 | E90: Секатор 228 мм професійний для великих рук Bellota (3505-23.B) Іспанія | F90: Секатор професійний Bellota 3512-22.B для великих рук | G90: 2054 | H90: 1909 | I90: назви схожі, але різні коди виробника
...

Sheet Підсумок
A1: Показник | B1: Значення | C1: Пояснення
A2: Звіт сформовано | B2: 08.10.2026 13:58
A3: Спільних товарів | B3: =COUNTA('Порівняння'!A2:A526)
A4: Потребують уваги | B4: =COUNTIF('Порівняння'!A2:A526,"Потребує уваги") | C4: червоні рядки на аркуші «Порівняння»
A5: Ваша ціна вища за орієнтир | B5: =COUNTIF('Порівняння'!A2:A526,"Ваша ціна вища")
A6: В нормі | B6: =COUNTIF('Порівняння'!A2:A526,"В нормі")
A7: Постачальник змінив ціну сьогодні | B7: =COUNT('Порівняння'!O2:O526)
A8: Немає в наявності в жодного постачальника | B8: 95 | C8: товар продається, а купити ніде
A9: Товарів у вашому фіді | B9: 3836
A10: Товарів у «Водоспад» | B10: 7072
A11: Товарів у «Клуб Рослин» | B11: 14183
A12: Пар на перевірку | B12: 2444 | C12: аркуш «Пари на перевірку»
A13: Як зіставлено | B13: код: 618, схожа назва: 35, назва: 5, модель: 16
A15: Пороги | C15: значення з config.json у репозиторії
A16: Допуск на округлення, грн | B16: 1 | C16: різниця в межах допуску не підсвічується
A17: Мінімальна націнка до ціни постачальника, % | B17: 0 | C17: нижче цього рядок червоний
A18: Максимальна націнка до ціни постачальника, % | B18: 0 | C18: вище цього рядок помаранчевий
